<?xml version="1.0" ?>
<!-- =================================================================================== -->
<!-- |    This document was autogenerated by xacro from taurob_tracker.urdf.xacro      | -->
<!-- |    EDITING THIS FILE BY HAND IS NOT RECOMMENDED                                 | -->
<!-- =================================================================================== -->
<robot name="taurob_tracker">
  <!-- create agx interfaces for the track motors? -->
  <link name="base_link"/>
  <joint name="chassis_joint" type="fixed">
    <origin rpy="0 0 0" xyz="0.122 0 0.193"/>
    <parent link="base_link"/>
    <child link="chassis_link"/>
  </joint>
  <link name="flipper_link_1">
    <inertial>
      <origin rpy="0 0 0" xyz="0.24 0.0 0.0"/>
      <mass value="1.0"/>
      <inertia ixx="0.00020421835841666664" ixy="0.0" ixz="0.0" iyy="0.020859296483416667" iyz="0.0" izz="0.021011588541666668"/>
    </inertial>
    <origin rpy="0 0 0" xyz="0 0 0"/>
    <visual>
      <origin rpy="1.5707963267948966 0 0" xyz="0.319 -0.29 0.0"/>
      <geometry>
        <cylinder length="0.04625" radius="0.065"/>
      </geometry>
      <material name="black">
        <color rgba="0.8 0.8 0.8 1"/>
      </material>
    </visual>
    <visual>
      <origin rpy="1.5707963267948966 0 0" xyz="0 -0.29 0.0"/>
      <geometry>
        <cylinder length="0.04625" radius="0.065"/>
      </geometry>
      <material name="black">
        <color rgba="0.8 0.8 0.8 1"/>
      </material>
    </visual>
    <visual>
      <origin rpy="0 0 0" xyz="0.1595 -0.29 0.0"/>
      <geometry>
        <box size="0.319 0.04625 0.13"/>
      </geometry>
      <material name="black">
        <color rgba="0.8 0.8 0.8 1"/>
      </material>
    </visual>
    <visual>
      <origin rpy="1.5707963267948966 0 0" xyz="0.319 0.29 0.0"/>
      <geometry>
        <cylinder length="0.04625" radius="0.065"/>
      </geometry>
      <material name="black">
        <color rgba="0.8 0.8 0.8 1"/>
      </material>
    </visual>
    <visual>
      <origin rpy="1.5707963267948966 0 0" xyz="0 0.29 0.0"/>
      <geometry>
        <cylinder length="0.04625" radius="0.065"/>
      </geometry>
      <material name="black">
        <color rgba="0.8 0.8 0.8 1"/>
      </material>
    </visual>
    <visual>
      <origin rpy="0 0 0" xyz="0.1595 0.29 0.0"/>
      <geometry>
        <box size="0.319 0.04625 0.13"/>
      </geometry>
      <material name="black">
        <color rgba="0.8 0.8 0.8 1"/>
      </material>
    </visual>
    <collision>
      <origin rpy="1.5707963267948966 0 0" xyz="0.319 -0.29 0.0"/>
      <geometry>
        <cylinder length="0.04625" radius="0.065"/>
      </geometry>
    </collision>
    <collision>
      <origin rpy="1.5707963267948966 0 0" xyz="0 -0.29 0.0"/>
      <geometry>
        <cylinder length="0.04625" radius="0.065"/>
      </geometry>
    </collision>
    <collision>
      <origin rpy="0 0 0" xyz="0.1595 -0.29 0.0"/>
      <geometry>
        <box size="0.319 0.04625 0.13"/>
      </geometry>
    </collision>
    <collision>
      <origin rpy="1.5707963267948966 0 0" xyz="0.319 0.29 0.0"/>
      <geometry>
        <cylinder length="0.04625" radius="0.065"/>
      </geometry>
    </collision>
    <collision>
      <origin rpy="1.5707963267948966 0 0" xyz="0 0.29 0.0"/>
      <geometry>
        <cylinder length="0.04625" radius="0.065"/>
      </geometry>
    </collision>
    <collision>
      <origin rpy="0 0 0" xyz="0.1595 0.29 0.0"/>
      <geometry>
        <box size="0.319 0.04625 0.13"/>
      </geometry>
    </collision>
  </link>
  <joint name="flipper_joint" type="revolute">
    <origin rpy="0 0 0" xyz="-0.07100000000000001 0 -0.09"/>
    <axis xyz="0 1 0"/>
    <limit effort="10000" lower="-0.8726646259971648" upper="0.5235987755982988" velocity="0.5235987755982988"/>
    <!--      <safety_controller soft_lower_limit="${-25 * pi / 180}"
                         soft_upper_limit="${45 * pi / 180}"
                         k_position="${100}"
                         k_velocity="${2}"/>-->
    <parent link="chassis_link"/>
    <child link="flipper_link_1"/>
  </joint>
  <link name="chassis_link">
    <inertial>
      <origin rpy="0 0 0" xyz="-0.25 0.0 -0.05"/>
      <mass value="30"/>
      <inertia ixx="0.7250000000000001" ixy="0.0" ixz="0.0" iyy="1.189" iyz="0.0" izz="1.714"/>
    </inertial>
    <!--Primitives with materials need to be used before .dae, otherwise material does not get applied-->
    <visual>
      <origin rpy="0 0 0" xyz="0.0 0.0 0.0"/>
      <geometry>
        <mesh filename="package://taurob_agx_bringup/meshes/tracker_chassis_no_tracks.dae"/>
      </geometry>
    </visual>
    <!--Chassis middle-->
    <collision>
      <origin rpy="0 0 0" xyz="0.0 0.0 0.0"/>
      <geometry>
        <mesh filename="package://taurob_agx_bringup/meshes/tracker_chassis_no_tracks.dae"/>
      </geometry>
    </collision>
  </link>
  <!-- active wheels -->
  <!--link name="left_wheel">
    <visual>
      <origin rpy="1.5707963267948966 0 0" xyz="0.0 0.0 0.0"/>
      <geometry>
        <cylinder length="0.04625" radius="0.13"/>
      </geometry>
      <material name="wheel_black">
        <color rgba="0 0 0 1"/>
      </material>
    </visual>
    <collision>
      <origin rpy="1.5707963267948966 0 0" xyz="0.0 0.0 0.0"/>
      <geometry>
        <cylinder length="0.04625" radius="0.13"/>
      </geometry>
    </collision>
  </link>
  <joint name="left_wheel_joint" type="continuous">
    <origin rpy="0 0 0" xyz="-0.07100000000000001 0.23374999999999999 -0.09"/>
    <axis xyz="0 1 0"/>
    <parent link="chassis_link"/>
    <child link="left_wheel"/>
  </joint>
  <link name="right_wheel">
    <visual>
      <origin rpy="1.5707963267948966 0 0" xyz="0.0 0.0 0.0"/>
      <geometry>
        <cylinder length="0.04625" radius="0.13"/>
      </geometry>
      <material name="wheel_black">
        <color rgba="0 0 0 1"/>
      </material>
    </visual>
    <collision>
      <origin rpy="1.5707963267948966 0 0" xyz="0.0 0.0 0.0"/>
      <geometry>
        <cylinder length="0.04625" radius="0.13"/>
      </geometry>
    </collision>
  </link>
  <joint name="right_wheel_joint" type="continuous">
    <origin rpy="0 0 0" xyz="-0.07100000000000001 -0.23374999999999999 -0.09"/>
    <axis xyz="0 1 0"/>
    <parent link="chassis_link"/>
    <child link="right_wheel"/>
  </joint-->
  <macro name="arm_link_0_collision_geom_marco">
    <!--Lower block-->
    <collision>
      <origin rpy="0 0 0" xyz="0.0 0.0 0.0"/>
      <geometry>
        <box size="0.1 0.1 0.08"/>
      </geometry>
      <material name="DarkGrey">
        <color rgba="0.6 0.6 0.6 1"/>
      </material>
    </collision>
    <!--Rounded part-->
    <collision>
      <origin rpy="1.5707963267948966 0 1.5707963267948966" xyz="-0.0265 0 0.055"/>
      <geometry>
        <cylinder length="0.043" radius="0.048"/>
      </geometry>
    </collision>
    <!--Angled block-->
    <collision>
      <origin rpy="0 -0.5654866776461628 0" xyz="0.02 0.0 0.06"/>
      <geometry>
        <box size="0.01 0.1 0.1"/>
      </geometry>
      1#
    
    </collision>
  </macro>
  <macro name="arm_link_1_collision_geom_marco">
    <collision>
      <origin rpy="0 0 0" xyz="-0.045 0.2755  0.0385"/>
      <geometry>
        <box size="0.09 0.451  0.104"/>
      </geometry>
    </collision>
    <collision>
      <origin rpy="0 0 0" xyz="-0.045  0.551  0.0225"/>
      <geometry>
        <box size="0.09 0.1  0.136"/>
      </geometry>
    </collision>
    <collision>
      <origin rpy="0 0 0" xyz="-0.045  0.0  0.0225"/>
      <geometry>
        <box size="0.09 0.1  0.136"/>
      </geometry>
    </collision>
  </macro>
  <macro name="arm_link_2_collision_geom_marco">
    <collision>
      <origin rpy="0 0 0" xyz="0.0365 -0.20825 0.0"/>
      <geometry>
        <box size="0.073 0.5125 0.086"/>
      </geometry>
    </collision>
  </macro>
  <macro name="arm_link_3_collision_geom_simple_eef__marco">
    <collision>
      <origin rpy="0 0 0" xyz="0.045 -0.06480999999999999 0.0"/>
      <geometry>
        <box size="0.07 0.208 0.091"/>
      </geometry>
    </collision>
  </macro>
  <macro name="arm_link_3_collision_geom_gripper_marco">
    <collision>
      <origin rpy="0 0 0" xyz=" -0.04357 0.04 0.0225"/>
      <geometry>
        <box size=" 0.1518 0.07893 0.09334"/>
      </geometry>
    </collision>
  </macro>
  <macro name="arm_link_4_collision_geom_marco">
    <collision>
      <origin rpy="0 0 0" xyz="-0.06 0.0 0.0"/>
      <geometry>
        <box size="0.12 0.05 0.05"/>
      </geometry>
    </collision>
    <collision>
      <origin rpy="0 0 0" xyz="-0.07 0.0 0.0"/>
      <geometry>
        <box size="0.06 0.13 0.04"/>
      </geometry>
    </collision>
  </macro>
  <macro name="gripper_link_1_collision_geom_marco">
    <!--Use simple geom below instead of two box meshes-->
    <!--
    <collision>
      <origin xyz="0.0 0.0 0.0" rpy="0 0 0" />
      <geometry>
        <mesh filename="package://taurob_arm_description/meshes/tgripper_link_1.stl"/>
      </geometry>
    </collision>
    -->
    <collision>
      <origin rpy="0 0 0" xyz="0.04 0.0 -0.035"/>
      <geometry>
        <box size="0.07 0.01 0.08"/>
      </geometry>
    </collision>
  </macro>
  <macro name="gripper_link_2_collision_geom_marco">
    <collision>
      <origin rpy="0 0 0" xyz="0.07 -0.025 0.0"/>
      <geometry>
        <box size="0.10 0.01 0.055"/>
      </geometry>
    </collision>
  </macro>
  <joint name="arm_joint_0" type="revolute">
    <origin rpy="0 0 1.5707595" xyz="0.0 0 0.0"/>
    <axis xyz="0 0 1"/>
    <limit effort="1000" lower="-3.141592653589793" upper="3.141592653589793" velocity="0.5235987755982988"/>
    <!--        <safety_controller soft_lower_limit="${-168 * pi / 180}"
      soft_upper_limit="${168 * pi / 180}"
      k_position="${100}"
      k_velocity="${2}"/>-->
    <parent link="chassis_link"/>
    <child link="arm_link_0"/>
  </joint>
  <link name="arm_link_0">
    <inertial>
      <origin rpy="0 0 0" xyz="0.0 0.0 0.089255"/>
      <mass value="2.0"/>
      <inertia ixx="0.006155296683333333" ixy="0.0" ixz="0.0" iyy="0.006696796683333333" iyz="0.0" izz="0.002466833333333333"/>
    </inertial>
    <visual>
      <origin rpy="0 0 0" xyz="0.0 0.0 0.0"/>
      <geometry>
        <mesh filename="package://taurob_agx_bringup/meshes/tarm_link_0_detailed.stl"/>
      </geometry>
      <material name="DarkGrey">
        <color rgba="0.3 0.3 0.3 1"/>
      </material>
    </visual>
    <arm_link_0_collision_geom_marco/>
  </link>
  <joint name="arm_joint_1" type="revolute">
    <origin rpy="0 0 0" xyz="-0.067 0.0 0.06"/>
    <axis xyz="1 0 0"/>
    <limit effort="1000" lower="0.0" upper="3.141592653589793" velocity="0.5235987755982988"/>
    <!--        <safety_controller soft_lower_limit="${-168 * pi / 180}"
      soft_upper_limit="${168 * pi / 180}"
      k_position="${100}"
      k_velocity="${2}"/>-->
    <parent link="arm_link_0"/>
    <child link="arm_link_1"/>
  </joint>
  <link name="arm_link_1">
    <inertial>
      <origin rpy="0 0 0" xyz="-0.055 0.2755  0.0225"/>
      <mass value="7.0"/>
      <inertia ixx="0.2580065833333333" ixy="0.0" ixz="0.0" iyy="0.015514333333333333" iyz="0.0" izz="0.25194225"/>
    </inertial>
    <visual>
      <origin rpy="0 0 0" xyz="0.0 0.0 0.0"/>
      <geometry>
        <mesh filename="package://taurob_agx_bringup/meshes/tarm_link_1.stl"/>
      </geometry>
      <material name="DarkGrey">
        <color rgba="0.3 0.3 0.3 1"/>
      </material>
    </visual>
    <arm_link_1_collision_geom_marco/>
  </link>
  <joint name="arm_joint_2" type="revolute">
    <origin rpy="0 0 0" xyz="0.022 0.551 0.0"/>
    <axis xyz="-1 0 0"/>
    <limit effort="1000" lower="0.0" upper="3.0543261909900763" velocity="0.5235987755982988"/>
    <!--        <safety_controller soft_lower_limit="${-168 * pi / 180}"
      soft_upper_limit="${168 * pi / 180}"
      k_position="${100}"
      k_velocity="${2}"/>-->
    <parent link="arm_link_1"/>
    <child link="arm_link_2"/>
  </joint>
  <link name="arm_link_2">
    <inertial>
      <origin rpy="0 0 0" xyz="0.047 -0.20825 0.0"/>
      <mass value="6.0"/>
      <inertia ixx="0.135026125" ixy="0.0" ixz="0.0" iyy="0.006362499999999999" iyz="0.0" izz="0.13399262499999998"/>
    </inertial>
    <visual>
      <origin rpy="0 0 0" xyz="0.0 0.0 0.0"/>
      <geometry>
        <mesh filename="package://taurob_agx_bringup/meshes/tarm_link_2.stl"/>
      </geometry>
      <material name="DarkGrey">
        <color rgba="0.3 0.3 0.3 1"/>
      </material>
    </visual>
    <arm_link_2_collision_geom_marco/>
  </link>
  <!--Needed for simulation-->
  <transmission name="arm_joint_0_joint_transmssion">
    <type>transmission_interface/SimpleTransmission</type>
    <joint name="arm_joint_0">
      <hardwareInterface>EffortJointInterface</hardwareInterface>
    </joint>
    <actuator name="arm_joint_0_motor">
      <hardwareInterface>EffortJointInterface</hardwareInterface>
      <mechanicalReduction>1</mechanicalReduction>
    </actuator>
  </transmission>
  <transmission name="arm_joint_1_joint_transmssion">
    <type>transmission_interface/SimpleTransmission</type>
    <joint name="arm_joint_1">
      <hardwareInterface>EffortJointInterface</hardwareInterface>
    </joint>
    <actuator name="arm_joint_1_motor">
      <hardwareInterface>EffortJointInterface</hardwareInterface>
      <mechanicalReduction>1</mechanicalReduction>
    </actuator>
  </transmission>
  <transmission name="arm_joint_2_joint_transmssion">
    <type>transmission_interface/SimpleTransmission</type>
    <joint name="arm_joint_2">
      <hardwareInterface>EffortJointInterface</hardwareInterface>
    </joint>
    <actuator name="arm_joint_2_motor">
      <hardwareInterface>EffortJointInterface</hardwareInterface>
      <mechanicalReduction>1</mechanicalReduction>
    </actuator>
  </transmission>
  <gazebo reference="arm_link_0">
    <material>Gazebo/Grey</material>
  </gazebo>
  <gazebo reference="arm_link_1">
    <material>Gazebo/Grey</material>
  </gazebo>
  <gazebo reference="arm_link_2">
    <material>Gazebo/Grey</material>
  </gazebo>
  <gazebo>
    <!-- ros_control plugin -->
    <plugin filename="libgazebo_ros_control_select_joints.so" name="gazebo_ros_control_select_joints">
      <robotNamespace>arm_control</robotNamespace>
      <joints>arm_joint_0 arm_joint_1 arm_joint_2 arm_joint_3</joints>
    </plugin>
  </gazebo>
  <joint name="arm_joint_3" type="revolute">
    <origin rpy=" 0 0 0" xyz="0.096 -0.42 0"/>
    <axis xyz="-1 0 0"/>
    <limit effort="1000" lower="-3.141592653589793" upper="3.141592653589793" velocity="1.9198621771937625"/>
    <!--        <safety_controller soft_lower_limit="${-168 * pi / 180}"
      soft_upper_limit="${168 * pi / 180}"
      k_position="${100}"
      k_velocity="${2}"/>-->
    <parent link="arm_link_2"/>
    <child link="arm_link_3"/>
  </joint>
  <link name="arm_link_3">
    <inertial>
      <origin rpy="0 0 0" xyz="0.045 -0.06480999999999999 0.0"/>
      <mass value="2.0"/>
      <inertia ixx="0.008590833333333332" ixy="0.0" ixz="0.0" iyy="0.0021968333333333336" iyz="0.0" izz="0.008027333333333333"/>
    </inertial>
    <visual>
      <origin rpy="0 0 0" xyz="0.0 0.0 0.0"/>
      <geometry>
        <mesh filename="package://taurob_agx_bringup/meshes/tarm_link_3.stl"/>
      </geometry>
      <material name="DarkGrey">
        <color rgba="0.3 0.3 0.3 1"/>
      </material>
    </visual>
    <arm_link_3_collision_geom_simple_eef__marco/>
  </link>
  <transmission name="arm_joint_3_joint_transmssion">
    <type>transmission_interface/SimpleTransmission</type>
    <joint name="arm_joint_3">
      <hardwareInterface>EffortJointInterface</hardwareInterface>
    </joint>
    <actuator name="arm_joint_3_motor">
      <hardwareInterface>EffortJointInterface</hardwareInterface>
      <mechanicalReduction>1</mechanicalReduction>
    </actuator>
  </transmission>
  <gazebo reference="arm_link_3">
    <material>Gazebo/Grey</material>
  </gazebo>
  <ros2_control name="TaurobHardwareInterface" type="system">
    <hardware>
      <plugin>agx_sim_ros2/AGXHardwareInterface</plugin>
    </hardware>
    <joint name="flipper_joint">
      <param name="agx_name">flipper_joint</param>
      <param name="sign">1</param>
      <command_interface name="velocity">
        <param name="min">-2.0</param>
        <param name="max">2.0</param>
      </command_interface>
      <state_interface name="position">
        <param name="initial_value">0.0</param>
      </state_interface>
      <state_interface name="velocity"/>
    </joint>
    <joint name="arm_joint_0">
      <param name="agx_name">arm_joint_0</param>
      <param name="sign">1</param>
      <command_interface name="velocity">
        <param name="min">-2.0</param>
        <param name="max">2.0</param>
      </command_interface>
      <state_interface name="position">
        <param name="initial_value">0.0</param>
      </state_interface>
      <state_interface name="velocity"/>
    </joint>
    <joint name="arm_joint_1">
      <param name="agx_name">arm_joint_1</param>
      <param name="sign">1</param>
      <command_interface name="velocity">
        <param name="min">-2.0</param>
        <param name="max">2.0</param>
      </command_interface>
      <state_interface name="position">
        <param name="initial_value">0.0</param>
      </state_interface>
      <state_interface name="velocity"/>
    </joint>
    <joint name="arm_joint_2">
      <param name="agx_name">arm_joint_2</param>
      <param name="sign">1</param>
      <command_interface name="velocity">
        <param name="min">-2.0</param>
        <param name="max">2.0</param>
      </command_interface>
      <state_interface name="position">
        <param name="initial_value">0.0</param>
      </state_interface>
      <state_interface name="velocity"/>
    </joint>
    <joint name="arm_joint_3">
      <param name="agx_name">arm_joint_3</param>
      <param name="sign">1</param>
      <command_interface name="velocity">
        <param name="min">-2.0</param>
        <param name="max">2.0</param>
      </command_interface>
      <state_interface name="position">
        <param name="initial_value">0.0</param>
      </state_interface>
      <state_interface name="velocity"/>
    </joint>
    <joint name="left_wheel_joint">
      <param name="agx_name">left_wheel_joint</param>
      <param name="sign">1</param>
      <command_interface name="velocity">
        <param name="min">-2.0</param>
        <param name="max">2.0</param>
      </command_interface>
      <state_interface name="position"/>
      <state_interface name="velocity"/>
    </joint>
    <joint name="right_wheel_joint">
      <param name="agx_name">right_wheel_joint</param>
      <param name="sign">1</param>
      <command_interface name="velocity">
        <param name="min">-2.0</param>
        <param name="max">2.0</param>
      </command_interface>
      <state_interface name="position"/>
      <state_interface name="velocity"/>
    </joint>
  </ros2_control>
</robot>
